INFO: 2023-06-01 11:20:59,275 **********************************************************************************************************************
INFO: 2023-06-01 11:20:59,275 YOUR BOT IS CURRENTLY RUNNING VERSION  1.0.0
ERROR: 2023-06-01 11:21:21,381 Could not transact with/call contract function, is contract deployed correctly and chain synced?
Traceback (most recent call last):
  File "C:\Users\Administrator\AppData\Local\Programs\Python\Python310\lib\site-packages\web3\contract\utils.py", line 111, in call_contract_function
    output_data = w3.codec.decode(output_types, return_data)
  File "C:\Users\Administrator\AppData\Local\Programs\Python\Python310\lib\site-packages\eth_abi\codec.py", line 145, in decode
    return decoder(stream)
  File "C:\Users\Administrator\AppData\Local\Programs\Python\Python310\lib\site-packages\eth_abi\decoding.py", line 129, in __call__
    return self.decode(stream)
  File "C:\Users\Administrator\AppData\Local\Programs\Python\Python310\lib\site-packages\eth_utils\functional.py", line 45, in inner
    return callback(fn(*args, **kwargs))
  File "C:\Users\Administrator\AppData\Local\Programs\Python\Python310\lib\site-packages\eth_abi\decoding.py", line 175, in decode
    yield decoder(stream)
  File "C:\Users\Administrator\AppData\Local\Programs\Python\Python310\lib\site-packages\eth_abi\decoding.py", line 129, in __call__
    return self.decode(stream)
  File "C:\Users\Administrator\AppData\Local\Programs\Python\Python310\lib\site-packages\eth_abi\decoding.py", line 199, in decode
    raw_data = self.read_data_from_stream(stream)
  File "C:\Users\Administrator\AppData\Local\Programs\Python\Python310\lib\site-packages\eth_abi\decoding.py", line 306, in read_data_from_stream
    raise InsufficientDataBytes(
eth_abi.exceptions.InsufficientDataBytes: Tried to read 32 bytes.  Only got 0 bytes

The above exception was the direct cause of the following exception:

Traceback (most recent call last):
  File "D:\Python\alpha-kcc-dex-bot\AlphaBot.py", line 4793, in run
    tokens = load_tokens_file(command_line_args.tokens, True)
  File "D:\Python\alpha-kcc-dex-bot\AlphaBot.py", line 664, in load_tokens_file
    '_BASE_PRICE': calculate_base_price(),
  File "C:\Users\Administrator\AppData\Local\Programs\Python\Python310\lib\site-packages\cachetools\__init__.py", line 737, in wrapper
    v = func(*args, **kwargs)
  File "D:\Python\alpha-kcc-dex-bot\AlphaBot.py", line 3067, in calculate_base_price
    reserves = pair_contract.functions.getReserves().call()
  File "C:\Users\Administrator\AppData\Local\Programs\Python\Python310\lib\site-packages\web3\contract\contract.py", line 461, in call
    return call_contract_function(
  File "C:\Users\Administrator\AppData\Local\Programs\Python\Python310\lib\site-packages\web3\contract\utils.py", line 129, in call_contract_function
    raise BadFunctionCallOutput(msg) from e
web3.exceptions.BadFunctionCallOutput: Could not transact with/call contract function, is contract deployed correctly and chain synced?
INFO: 2023-06-01 11:21:21,384 ERROR. Please go to /log folder and open your logs: you will find more details.
ERROR: 2023-06-01 11:21:21,384 Could not transact with/call contract function, is contract deployed correctly and chain synced?
Traceback (most recent call last):
  File "C:\Users\Administrator\AppData\Local\Programs\Python\Python310\lib\site-packages\web3\contract\utils.py", line 111, in call_contract_function
    output_data = w3.codec.decode(output_types, return_data)
  File "C:\Users\Administrator\AppData\Local\Programs\Python\Python310\lib\site-packages\eth_abi\codec.py", line 145, in decode
    return decoder(stream)
  File "C:\Users\Administrator\AppData\Local\Programs\Python\Python310\lib\site-packages\eth_abi\decoding.py", line 129, in __call__
    return self.decode(stream)
  File "C:\Users\Administrator\AppData\Local\Programs\Python\Python310\lib\site-packages\eth_utils\functional.py", line 45, in inner
    return callback(fn(*args, **kwargs))
  File "C:\Users\Administrator\AppData\Local\Programs\Python\Python310\lib\site-packages\eth_abi\decoding.py", line 175, in decode
    yield decoder(stream)
  File "C:\Users\Administrator\AppData\Local\Programs\Python\Python310\lib\site-packages\eth_abi\decoding.py", line 129, in __call__
    return self.decode(stream)
  File "C:\Users\Administrator\AppData\Local\Programs\Python\Python310\lib\site-packages\eth_abi\decoding.py", line 199, in decode
    raw_data = self.read_data_from_stream(stream)
  File "C:\Users\Administrator\AppData\Local\Programs\Python\Python310\lib\site-packages\eth_abi\decoding.py", line 306, in read_data_from_stream
    raise InsufficientDataBytes(
eth_abi.exceptions.InsufficientDataBytes: Tried to read 32 bytes.  Only got 0 bytes

The above exception was the direct cause of the following exception:

Traceback (most recent call last):
  File "D:\Python\alpha-kcc-dex-bot\AlphaBot.py", line 5347, in runLoop
    run()
  File "D:\Python\alpha-kcc-dex-bot\AlphaBot.py", line 4793, in run
    tokens = load_tokens_file(command_line_args.tokens, True)
  File "D:\Python\alpha-kcc-dex-bot\AlphaBot.py", line 664, in load_tokens_file
    '_BASE_PRICE': calculate_base_price(),
  File "C:\Users\Administrator\AppData\Local\Programs\Python\Python310\lib\site-packages\cachetools\__init__.py", line 737, in wrapper
    v = func(*args, **kwargs)
  File "D:\Python\alpha-kcc-dex-bot\AlphaBot.py", line 3067, in calculate_base_price
    reserves = pair_contract.functions.getReserves().call()
  File "C:\Users\Administrator\AppData\Local\Programs\Python\Python310\lib\site-packages\web3\contract\contract.py", line 461, in call
    return call_contract_function(
  File "C:\Users\Administrator\AppData\Local\Programs\Python\Python310\lib\site-packages\web3\contract\utils.py", line 129, in call_contract_function
    raise BadFunctionCallOutput(msg) from e
web3.exceptions.BadFunctionCallOutput: Could not transact with/call contract function, is contract deployed correctly and chain synced?
ERROR: 2023-06-01 11:21:21,384 Could not transact with/call contract function, is contract deployed correctly and chain synced?
Traceback (most recent call last):
  File "C:\Users\Administrator\AppData\Local\Programs\Python\Python310\lib\site-packages\web3\contract\utils.py", line 111, in call_contract_function
    output_data = w3.codec.decode(output_types, return_data)
  File "C:\Users\Administrator\AppData\Local\Programs\Python\Python310\lib\site-packages\eth_abi\codec.py", line 145, in decode
    return decoder(stream)
  File "C:\Users\Administrator\AppData\Local\Programs\Python\Python310\lib\site-packages\eth_abi\decoding.py", line 129, in __call__
    return self.decode(stream)
  File "C:\Users\Administrator\AppData\Local\Programs\Python\Python310\lib\site-packages\eth_utils\functional.py", line 45, in inner
    return callback(fn(*args, **kwargs))
  File "C:\Users\Administrator\AppData\Local\Programs\Python\Python310\lib\site-packages\eth_abi\decoding.py", line 175, in decode
    yield decoder(stream)
  File "C:\Users\Administrator\AppData\Local\Programs\Python\Python310\lib\site-packages\eth_abi\decoding.py", line 129, in __call__
    return self.decode(stream)
  File "C:\Users\Administrator\AppData\Local\Programs\Python\Python310\lib\site-packages\eth_abi\decoding.py", line 199, in decode
    raw_data = self.read_data_from_stream(stream)
  File "C:\Users\Administrator\AppData\Local\Programs\Python\Python310\lib\site-packages\eth_abi\decoding.py", line 306, in read_data_from_stream
    raise InsufficientDataBytes(
eth_abi.exceptions.InsufficientDataBytes: Tried to read 32 bytes.  Only got 0 bytes

The above exception was the direct cause of the following exception:

Traceback (most recent call last):
  File "D:\Python\alpha-kcc-dex-bot\AlphaBot.py", line 5347, in runLoop
    run()
  File "D:\Python\alpha-kcc-dex-bot\AlphaBot.py", line 4793, in run
    tokens = load_tokens_file(command_line_args.tokens, True)
  File "D:\Python\alpha-kcc-dex-bot\AlphaBot.py", line 664, in load_tokens_file
    '_BASE_PRICE': calculate_base_price(),
  File "C:\Users\Administrator\AppData\Local\Programs\Python\Python310\lib\site-packages\cachetools\__init__.py", line 737, in wrapper
    v = func(*args, **kwargs)
  File "D:\Python\alpha-kcc-dex-bot\AlphaBot.py", line 3067, in calculate_base_price
    reserves = pair_contract.functions.getReserves().call()
  File "C:\Users\Administrator\AppData\Local\Programs\Python\Python310\lib\site-packages\web3\contract\contract.py", line 461, in call
    return call_contract_function(
  File "C:\Users\Administrator\AppData\Local\Programs\Python\Python310\lib\site-packages\web3\contract\utils.py", line 129, in call_contract_function
    raise BadFunctionCallOutput(msg) from e
web3.exceptions.BadFunctionCallOutput: Could not transact with/call contract function, is contract deployed correctly and chain synced?
ERROR: 2023-06-01 11:21:32,494 'ZONE'
Traceback (most recent call last):
  File "C:\Users\Administrator\AppData\Local\Programs\Python\Python310\lib\site-packages\web3\contract\utils.py", line 111, in call_contract_function
    output_data = w3.codec.decode(output_types, return_data)
  File "C:\Users\Administrator\AppData\Local\Programs\Python\Python310\lib\site-packages\eth_abi\codec.py", line 145, in decode
    return decoder(stream)
  File "C:\Users\Administrator\AppData\Local\Programs\Python\Python310\lib\site-packages\eth_abi\decoding.py", line 129, in __call__
    return self.decode(stream)
  File "C:\Users\Administrator\AppData\Local\Programs\Python\Python310\lib\site-packages\eth_utils\functional.py", line 45, in inner
    return callback(fn(*args, **kwargs))
  File "C:\Users\Administrator\AppData\Local\Programs\Python\Python310\lib\site-packages\eth_abi\decoding.py", line 175, in decode
    yield decoder(stream)
  File "C:\Users\Administrator\AppData\Local\Programs\Python\Python310\lib\site-packages\eth_abi\decoding.py", line 129, in __call__
    return self.decode(stream)
  File "C:\Users\Administrator\AppData\Local\Programs\Python\Python310\lib\site-packages\eth_abi\decoding.py", line 199, in decode
    raw_data = self.read_data_from_stream(stream)
  File "C:\Users\Administrator\AppData\Local\Programs\Python\Python310\lib\site-packages\eth_abi\decoding.py", line 306, in read_data_from_stream
    raise InsufficientDataBytes(
eth_abi.exceptions.InsufficientDataBytes: Tried to read 32 bytes.  Only got 0 bytes

The above exception was the direct cause of the following exception:

Traceback (most recent call last):
  File "D:\Python\alpha-kcc-dex-bot\AlphaBot.py", line 5347, in runLoop
    run()
  File "D:\Python\alpha-kcc-dex-bot\AlphaBot.py", line 4793, in run
    tokens = load_tokens_file(command_line_args.tokens, True)
  File "D:\Python\alpha-kcc-dex-bot\AlphaBot.py", line 664, in load_tokens_file
    '_BASE_PRICE': calculate_base_price(),
  File "C:\Users\Administrator\AppData\Local\Programs\Python\Python310\lib\site-packages\cachetools\__init__.py", line 737, in wrapper
    v = func(*args, **kwargs)
  File "D:\Python\alpha-kcc-dex-bot\AlphaBot.py", line 3067, in calculate_base_price
    reserves = pair_contract.functions.getReserves().call()
  File "C:\Users\Administrator\AppData\Local\Programs\Python\Python310\lib\site-packages\web3\contract\contract.py", line 461, in call
    return call_contract_function(
  File "C:\Users\Administrator\AppData\Local\Programs\Python\Python310\lib\site-packages\web3\contract\utils.py", line 129, in call_contract_function
    raise BadFunctionCallOutput(msg) from e
web3.exceptions.BadFunctionCallOutput: Could not transact with/call contract function, is contract deployed correctly and chain synced?

During handling of the above exception, another exception occurred:

Traceback (most recent call last):
  File "D:\Python\alpha-kcc-dex-bot\AlphaBot.py", line 4795, in run
    tokens = reload_tokens_file(command_line_args.tokens, True)
  File "D:\Python\alpha-kcc-dex-bot\AlphaBot.py", line 931, in reload_tokens_file
    '_LIQUIDITY_READY': _TOKENS_saved[token['SYMBOL']]['_LIQUIDITY_READY'],
KeyError: 'ZONE'
INFO: 2023-06-01 11:21:32,495 ERROR. Please go to /log folder and open your logs: you will find more details.
ERROR: 2023-06-01 11:21:32,495 'ZONE'
Traceback (most recent call last):
  File "C:\Users\Administrator\AppData\Local\Programs\Python\Python310\lib\site-packages\web3\contract\utils.py", line 111, in call_contract_function
    output_data = w3.codec.decode(output_types, return_data)
  File "C:\Users\Administrator\AppData\Local\Programs\Python\Python310\lib\site-packages\eth_abi\codec.py", line 145, in decode
    return decoder(stream)
  File "C:\Users\Administrator\AppData\Local\Programs\Python\Python310\lib\site-packages\eth_abi\decoding.py", line 129, in __call__
    return self.decode(stream)
  File "C:\Users\Administrator\AppData\Local\Programs\Python\Python310\lib\site-packages\eth_utils\functional.py", line 45, in inner
    return callback(fn(*args, **kwargs))
  File "C:\Users\Administrator\AppData\Local\Programs\Python\Python310\lib\site-packages\eth_abi\decoding.py", line 175, in decode
    yield decoder(stream)
  File "C:\Users\Administrator\AppData\Local\Programs\Python\Python310\lib\site-packages\eth_abi\decoding.py", line 129, in __call__
    return self.decode(stream)
  File "C:\Users\Administrator\AppData\Local\Programs\Python\Python310\lib\site-packages\eth_abi\decoding.py", line 199, in decode
    raw_data = self.read_data_from_stream(stream)
  File "C:\Users\Administrator\AppData\Local\Programs\Python\Python310\lib\site-packages\eth_abi\decoding.py", line 306, in read_data_from_stream
    raise InsufficientDataBytes(
eth_abi.exceptions.InsufficientDataBytes: Tried to read 32 bytes.  Only got 0 bytes

The above exception was the direct cause of the following exception:

Traceback (most recent call last):
  File "D:\Python\alpha-kcc-dex-bot\AlphaBot.py", line 5347, in runLoop
    run()
  File "D:\Python\alpha-kcc-dex-bot\AlphaBot.py", line 4793, in run
    tokens = load_tokens_file(command_line_args.tokens, True)
  File "D:\Python\alpha-kcc-dex-bot\AlphaBot.py", line 664, in load_tokens_file
    '_BASE_PRICE': calculate_base_price(),
  File "C:\Users\Administrator\AppData\Local\Programs\Python\Python310\lib\site-packages\cachetools\__init__.py", line 737, in wrapper
    v = func(*args, **kwargs)
  File "D:\Python\alpha-kcc-dex-bot\AlphaBot.py", line 3067, in calculate_base_price
    reserves = pair_contract.functions.getReserves().call()
  File "C:\Users\Administrator\AppData\Local\Programs\Python\Python310\lib\site-packages\web3\contract\contract.py", line 461, in call
    return call_contract_function(
  File "C:\Users\Administrator\AppData\Local\Programs\Python\Python310\lib\site-packages\web3\contract\utils.py", line 129, in call_contract_function
    raise BadFunctionCallOutput(msg) from e
web3.exceptions.BadFunctionCallOutput: Could not transact with/call contract function, is contract deployed correctly and chain synced?

During handling of the above exception, another exception occurred:

Traceback (most recent call last):
  File "D:\Python\alpha-kcc-dex-bot\AlphaBot.py", line 5347, in runLoop
    run()
  File "D:\Python\alpha-kcc-dex-bot\AlphaBot.py", line 4795, in run
    tokens = reload_tokens_file(command_line_args.tokens, True)
  File "D:\Python\alpha-kcc-dex-bot\AlphaBot.py", line 931, in reload_tokens_file
    '_LIQUIDITY_READY': _TOKENS_saved[token['SYMBOL']]['_LIQUIDITY_READY'],
KeyError: 'ZONE'
ERROR: 2023-06-01 11:21:32,495 'ZONE'
Traceback (most recent call last):
  File "C:\Users\Administrator\AppData\Local\Programs\Python\Python310\lib\site-packages\web3\contract\utils.py", line 111, in call_contract_function
    output_data = w3.codec.decode(output_types, return_data)
  File "C:\Users\Administrator\AppData\Local\Programs\Python\Python310\lib\site-packages\eth_abi\codec.py", line 145, in decode
    return decoder(stream)
  File "C:\Users\Administrator\AppData\Local\Programs\Python\Python310\lib\site-packages\eth_abi\decoding.py", line 129, in __call__
    return self.decode(stream)
  File "C:\Users\Administrator\AppData\Local\Programs\Python\Python310\lib\site-packages\eth_utils\functional.py", line 45, in inner
    return callback(fn(*args, **kwargs))
  File "C:\Users\Administrator\AppData\Local\Programs\Python\Python310\lib\site-packages\eth_abi\decoding.py", line 175, in decode
    yield decoder(stream)
  File "C:\Users\Administrator\AppData\Local\Programs\Python\Python310\lib\site-packages\eth_abi\decoding.py", line 129, in __call__
    return self.decode(stream)
  File "C:\Users\Administrator\AppData\Local\Programs\Python\Python310\lib\site-packages\eth_abi\decoding.py", line 199, in decode
    raw_data = self.read_data_from_stream(stream)
  File "C:\Users\Administrator\AppData\Local\Programs\Python\Python310\lib\site-packages\eth_abi\decoding.py", line 306, in read_data_from_stream
    raise InsufficientDataBytes(
eth_abi.exceptions.InsufficientDataBytes: Tried to read 32 bytes.  Only got 0 bytes

The above exception was the direct cause of the following exception:

Traceback (most recent call last):
  File "D:\Python\alpha-kcc-dex-bot\AlphaBot.py", line 5347, in runLoop
    run()
  File "D:\Python\alpha-kcc-dex-bot\AlphaBot.py", line 4793, in run
    tokens = load_tokens_file(command_line_args.tokens, True)
  File "D:\Python\alpha-kcc-dex-bot\AlphaBot.py", line 664, in load_tokens_file
    '_BASE_PRICE': calculate_base_price(),
  File "C:\Users\Administrator\AppData\Local\Programs\Python\Python310\lib\site-packages\cachetools\__init__.py", line 737, in wrapper
    v = func(*args, **kwargs)
  File "D:\Python\alpha-kcc-dex-bot\AlphaBot.py", line 3067, in calculate_base_price
    reserves = pair_contract.functions.getReserves().call()
  File "C:\Users\Administrator\AppData\Local\Programs\Python\Python310\lib\site-packages\web3\contract\contract.py", line 461, in call
    return call_contract_function(
  File "C:\Users\Administrator\AppData\Local\Programs\Python\Python310\lib\site-packages\web3\contract\utils.py", line 129, in call_contract_function
    raise BadFunctionCallOutput(msg) from e
web3.exceptions.BadFunctionCallOutput: Could not transact with/call contract function, is contract deployed correctly and chain synced?

During handling of the above exception, another exception occurred:

Traceback (most recent call last):
  File "D:\Python\alpha-kcc-dex-bot\AlphaBot.py", line 5347, in runLoop
    run()
  File "D:\Python\alpha-kcc-dex-bot\AlphaBot.py", line 4795, in run
    tokens = reload_tokens_file(command_line_args.tokens, True)
  File "D:\Python\alpha-kcc-dex-bot\AlphaBot.py", line 931, in reload_tokens_file
    '_LIQUIDITY_READY': _TOKENS_saved[token['SYMBOL']]['_LIQUIDITY_READY'],
KeyError: 'ZONE'
INFO: 2023-06-01 12:10:22,979 **********************************************************************************************************************
INFO: 2023-06-01 12:10:22,980 YOUR BOT IS CURRENTLY RUNNING VERSION  1.0.0
INFO: 2023-06-01 12:10:46,879 **********************************************************************************************************************
INFO: 2023-06-01 12:10:46,879 YOUR BOT IS CURRENTLY RUNNING VERSION  1.0.0
ERROR: 2023-06-01 12:10:56,961 Could not transact with/call contract function, is contract deployed correctly and chain synced?
Traceback (most recent call last):
  File "C:\Users\Administrator\AppData\Local\Programs\Python\Python310\lib\site-packages\web3\contract\utils.py", line 111, in call_contract_function
    output_data = w3.codec.decode(output_types, return_data)
  File "C:\Users\Administrator\AppData\Local\Programs\Python\Python310\lib\site-packages\eth_abi\codec.py", line 145, in decode
    return decoder(stream)
  File "C:\Users\Administrator\AppData\Local\Programs\Python\Python310\lib\site-packages\eth_abi\decoding.py", line 129, in __call__
    return self.decode(stream)
  File "C:\Users\Administrator\AppData\Local\Programs\Python\Python310\lib\site-packages\eth_utils\functional.py", line 45, in inner
    return callback(fn(*args, **kwargs))
  File "C:\Users\Administrator\AppData\Local\Programs\Python\Python310\lib\site-packages\eth_abi\decoding.py", line 175, in decode
    yield decoder(stream)
  File "C:\Users\Administrator\AppData\Local\Programs\Python\Python310\lib\site-packages\eth_abi\decoding.py", line 129, in __call__
    return self.decode(stream)
  File "C:\Users\Administrator\AppData\Local\Programs\Python\Python310\lib\site-packages\eth_abi\decoding.py", line 199, in decode
    raw_data = self.read_data_from_stream(stream)
  File "C:\Users\Administrator\AppData\Local\Programs\Python\Python310\lib\site-packages\eth_abi\decoding.py", line 306, in read_data_from_stream
    raise InsufficientDataBytes(
eth_abi.exceptions.InsufficientDataBytes: Tried to read 32 bytes.  Only got 0 bytes

The above exception was the direct cause of the following exception:

Traceback (most recent call last):
  File "D:\Python\alpha-kcc-dex-bot\AlphaBot.py", line 4793, in run
    tokens = load_tokens_file(command_line_args.tokens, True)
  File "D:\Python\alpha-kcc-dex-bot\AlphaBot.py", line 664, in load_tokens_file
    '_BASE_PRICE': calculate_base_price(),
  File "C:\Users\Administrator\AppData\Local\Programs\Python\Python310\lib\site-packages\cachetools\__init__.py", line 737, in wrapper
    v = func(*args, **kwargs)
  File "D:\Python\alpha-kcc-dex-bot\AlphaBot.py", line 3067, in calculate_base_price
    reserves = pair_contract.functions.getReserves().call()
  File "C:\Users\Administrator\AppData\Local\Programs\Python\Python310\lib\site-packages\web3\contract\contract.py", line 461, in call
    return call_contract_function(
  File "C:\Users\Administrator\AppData\Local\Programs\Python\Python310\lib\site-packages\web3\contract\utils.py", line 129, in call_contract_function
    raise BadFunctionCallOutput(msg) from e
web3.exceptions.BadFunctionCallOutput: Could not transact with/call contract function, is contract deployed correctly and chain synced?
INFO: 2023-06-01 12:10:56,964 ERROR. Please go to /log folder and open your logs: you will find more details.
ERROR: 2023-06-01 12:10:56,964 Could not transact with/call contract function, is contract deployed correctly and chain synced?
Traceback (most recent call last):
  File "C:\Users\Administrator\AppData\Local\Programs\Python\Python310\lib\site-packages\web3\contract\utils.py", line 111, in call_contract_function
    output_data = w3.codec.decode(output_types, return_data)
  File "C:\Users\Administrator\AppData\Local\Programs\Python\Python310\lib\site-packages\eth_abi\codec.py", line 145, in decode
    return decoder(stream)
  File "C:\Users\Administrator\AppData\Local\Programs\Python\Python310\lib\site-packages\eth_abi\decoding.py", line 129, in __call__
    return self.decode(stream)
  File "C:\Users\Administrator\AppData\Local\Programs\Python\Python310\lib\site-packages\eth_utils\functional.py", line 45, in inner
    return callback(fn(*args, **kwargs))
  File "C:\Users\Administrator\AppData\Local\Programs\Python\Python310\lib\site-packages\eth_abi\decoding.py", line 175, in decode
    yield decoder(stream)
  File "C:\Users\Administrator\AppData\Local\Programs\Python\Python310\lib\site-packages\eth_abi\decoding.py", line 129, in __call__
    return self.decode(stream)
  File "C:\Users\Administrator\AppData\Local\Programs\Python\Python310\lib\site-packages\eth_abi\decoding.py", line 199, in decode
    raw_data = self.read_data_from_stream(stream)
  File "C:\Users\Administrator\AppData\Local\Programs\Python\Python310\lib\site-packages\eth_abi\decoding.py", line 306, in read_data_from_stream
    raise InsufficientDataBytes(
eth_abi.exceptions.InsufficientDataBytes: Tried to read 32 bytes.  Only got 0 bytes

The above exception was the direct cause of the following exception:

Traceback (most recent call last):
  File "D:\Python\alpha-kcc-dex-bot\AlphaBot.py", line 5347, in runLoop
    run()
  File "D:\Python\alpha-kcc-dex-bot\AlphaBot.py", line 4793, in run
    tokens = load_tokens_file(command_line_args.tokens, True)
  File "D:\Python\alpha-kcc-dex-bot\AlphaBot.py", line 664, in load_tokens_file
    '_BASE_PRICE': calculate_base_price(),
  File "C:\Users\Administrator\AppData\Local\Programs\Python\Python310\lib\site-packages\cachetools\__init__.py", line 737, in wrapper
    v = func(*args, **kwargs)
  File "D:\Python\alpha-kcc-dex-bot\AlphaBot.py", line 3067, in calculate_base_price
    reserves = pair_contract.functions.getReserves().call()
  File "C:\Users\Administrator\AppData\Local\Programs\Python\Python310\lib\site-packages\web3\contract\contract.py", line 461, in call
    return call_contract_function(
  File "C:\Users\Administrator\AppData\Local\Programs\Python\Python310\lib\site-packages\web3\contract\utils.py", line 129, in call_contract_function
    raise BadFunctionCallOutput(msg) from e
web3.exceptions.BadFunctionCallOutput: Could not transact with/call contract function, is contract deployed correctly and chain synced?
ERROR: 2023-06-01 12:10:56,964 Could not transact with/call contract function, is contract deployed correctly and chain synced?
Traceback (most recent call last):
  File "C:\Users\Administrator\AppData\Local\Programs\Python\Python310\lib\site-packages\web3\contract\utils.py", line 111, in call_contract_function
    output_data = w3.codec.decode(output_types, return_data)
  File "C:\Users\Administrator\AppData\Local\Programs\Python\Python310\lib\site-packages\eth_abi\codec.py", line 145, in decode
    return decoder(stream)
  File "C:\Users\Administrator\AppData\Local\Programs\Python\Python310\lib\site-packages\eth_abi\decoding.py", line 129, in __call__
    return self.decode(stream)
  File "C:\Users\Administrator\AppData\Local\Programs\Python\Python310\lib\site-packages\eth_utils\functional.py", line 45, in inner
    return callback(fn(*args, **kwargs))
  File "C:\Users\Administrator\AppData\Local\Programs\Python\Python310\lib\site-packages\eth_abi\decoding.py", line 175, in decode
    yield decoder(stream)
  File "C:\Users\Administrator\AppData\Local\Programs\Python\Python310\lib\site-packages\eth_abi\decoding.py", line 129, in __call__
    return self.decode(stream)
  File "C:\Users\Administrator\AppData\Local\Programs\Python\Python310\lib\site-packages\eth_abi\decoding.py", line 199, in decode
    raw_data = self.read_data_from_stream(stream)
  File "C:\Users\Administrator\AppData\Local\Programs\Python\Python310\lib\site-packages\eth_abi\decoding.py", line 306, in read_data_from_stream
    raise InsufficientDataBytes(
eth_abi.exceptions.InsufficientDataBytes: Tried to read 32 bytes.  Only got 0 bytes

The above exception was the direct cause of the following exception:

Traceback (most recent call last):
  File "D:\Python\alpha-kcc-dex-bot\AlphaBot.py", line 5347, in runLoop
    run()
  File "D:\Python\alpha-kcc-dex-bot\AlphaBot.py", line 4793, in run
    tokens = load_tokens_file(command_line_args.tokens, True)
  File "D:\Python\alpha-kcc-dex-bot\AlphaBot.py", line 664, in load_tokens_file
    '_BASE_PRICE': calculate_base_price(),
  File "C:\Users\Administrator\AppData\Local\Programs\Python\Python310\lib\site-packages\cachetools\__init__.py", line 737, in wrapper
    v = func(*args, **kwargs)
  File "D:\Python\alpha-kcc-dex-bot\AlphaBot.py", line 3067, in calculate_base_price
    reserves = pair_contract.functions.getReserves().call()
  File "C:\Users\Administrator\AppData\Local\Programs\Python\Python310\lib\site-packages\web3\contract\contract.py", line 461, in call
    return call_contract_function(
  File "C:\Users\Administrator\AppData\Local\Programs\Python\Python310\lib\site-packages\web3\contract\utils.py", line 129, in call_contract_function
    raise BadFunctionCallOutput(msg) from e
web3.exceptions.BadFunctionCallOutput: Could not transact with/call contract function, is contract deployed correctly and chain synced?
ERROR: 2023-06-01 12:11:08,050 'ZONE'
Traceback (most recent call last):
  File "C:\Users\Administrator\AppData\Local\Programs\Python\Python310\lib\site-packages\web3\contract\utils.py", line 111, in call_contract_function
    output_data = w3.codec.decode(output_types, return_data)
  File "C:\Users\Administrator\AppData\Local\Programs\Python\Python310\lib\site-packages\eth_abi\codec.py", line 145, in decode
    return decoder(stream)
  File "C:\Users\Administrator\AppData\Local\Programs\Python\Python310\lib\site-packages\eth_abi\decoding.py", line 129, in __call__
    return self.decode(stream)
  File "C:\Users\Administrator\AppData\Local\Programs\Python\Python310\lib\site-packages\eth_utils\functional.py", line 45, in inner
    return callback(fn(*args, **kwargs))
  File "C:\Users\Administrator\AppData\Local\Programs\Python\Python310\lib\site-packages\eth_abi\decoding.py", line 175, in decode
    yield decoder(stream)
  File "C:\Users\Administrator\AppData\Local\Programs\Python\Python310\lib\site-packages\eth_abi\decoding.py", line 129, in __call__
    return self.decode(stream)
  File "C:\Users\Administrator\AppData\Local\Programs\Python\Python310\lib\site-packages\eth_abi\decoding.py", line 199, in decode
    raw_data = self.read_data_from_stream(stream)
  File "C:\Users\Administrator\AppData\Local\Programs\Python\Python310\lib\site-packages\eth_abi\decoding.py", line 306, in read_data_from_stream
    raise InsufficientDataBytes(
eth_abi.exceptions.InsufficientDataBytes: Tried to read 32 bytes.  Only got 0 bytes

The above exception was the direct cause of the following exception:

Traceback (most recent call last):
  File "D:\Python\alpha-kcc-dex-bot\AlphaBot.py", line 5347, in runLoop
    run()
  File "D:\Python\alpha-kcc-dex-bot\AlphaBot.py", line 4793, in run
    tokens = load_tokens_file(command_line_args.tokens, True)
  File "D:\Python\alpha-kcc-dex-bot\AlphaBot.py", line 664, in load_tokens_file
    '_BASE_PRICE': calculate_base_price(),
  File "C:\Users\Administrator\AppData\Local\Programs\Python\Python310\lib\site-packages\cachetools\__init__.py", line 737, in wrapper
    v = func(*args, **kwargs)
  File "D:\Python\alpha-kcc-dex-bot\AlphaBot.py", line 3067, in calculate_base_price
    reserves = pair_contract.functions.getReserves().call()
  File "C:\Users\Administrator\AppData\Local\Programs\Python\Python310\lib\site-packages\web3\contract\contract.py", line 461, in call
    return call_contract_function(
  File "C:\Users\Administrator\AppData\Local\Programs\Python\Python310\lib\site-packages\web3\contract\utils.py", line 129, in call_contract_function
    raise BadFunctionCallOutput(msg) from e
web3.exceptions.BadFunctionCallOutput: Could not transact with/call contract function, is contract deployed correctly and chain synced?

During handling of the above exception, another exception occurred:

Traceback (most recent call last):
  File "D:\Python\alpha-kcc-dex-bot\AlphaBot.py", line 4795, in run
    tokens = reload_tokens_file(command_line_args.tokens, True)
  File "D:\Python\alpha-kcc-dex-bot\AlphaBot.py", line 931, in reload_tokens_file
    '_LIQUIDITY_READY': _TOKENS_saved[token['SYMBOL']]['_LIQUIDITY_READY'],
KeyError: 'ZONE'
INFO: 2023-06-01 12:11:08,050 ERROR. Please go to /log folder and open your logs: you will find more details.
ERROR: 2023-06-01 12:11:08,051 'ZONE'
Traceback (most recent call last):
  File "C:\Users\Administrator\AppData\Local\Programs\Python\Python310\lib\site-packages\web3\contract\utils.py", line 111, in call_contract_function
    output_data = w3.codec.decode(output_types, return_data)
  File "C:\Users\Administrator\AppData\Local\Programs\Python\Python310\lib\site-packages\eth_abi\codec.py", line 145, in decode
    return decoder(stream)
  File "C:\Users\Administrator\AppData\Local\Programs\Python\Python310\lib\site-packages\eth_abi\decoding.py", line 129, in __call__
    return self.decode(stream)
  File "C:\Users\Administrator\AppData\Local\Programs\Python\Python310\lib\site-packages\eth_utils\functional.py", line 45, in inner
    return callback(fn(*args, **kwargs))
  File "C:\Users\Administrator\AppData\Local\Programs\Python\Python310\lib\site-packages\eth_abi\decoding.py", line 175, in decode
    yield decoder(stream)
  File "C:\Users\Administrator\AppData\Local\Programs\Python\Python310\lib\site-packages\eth_abi\decoding.py", line 129, in __call__
    return self.decode(stream)
  File "C:\Users\Administrator\AppData\Local\Programs\Python\Python310\lib\site-packages\eth_abi\decoding.py", line 199, in decode
    raw_data = self.read_data_from_stream(stream)
  File "C:\Users\Administrator\AppData\Local\Programs\Python\Python310\lib\site-packages\eth_abi\decoding.py", line 306, in read_data_from_stream
    raise InsufficientDataBytes(
eth_abi.exceptions.InsufficientDataBytes: Tried to read 32 bytes.  Only got 0 bytes

The above exception was the direct cause of the following exception:

Traceback (most recent call last):
  File "D:\Python\alpha-kcc-dex-bot\AlphaBot.py", line 5347, in runLoop
    run()
  File "D:\Python\alpha-kcc-dex-bot\AlphaBot.py", line 4793, in run
    tokens = load_tokens_file(command_line_args.tokens, True)
  File "D:\Python\alpha-kcc-dex-bot\AlphaBot.py", line 664, in load_tokens_file
    '_BASE_PRICE': calculate_base_price(),
  File "C:\Users\Administrator\AppData\Local\Programs\Python\Python310\lib\site-packages\cachetools\__init__.py", line 737, in wrapper
    v = func(*args, **kwargs)
  File "D:\Python\alpha-kcc-dex-bot\AlphaBot.py", line 3067, in calculate_base_price
    reserves = pair_contract.functions.getReserves().call()
  File "C:\Users\Administrator\AppData\Local\Programs\Python\Python310\lib\site-packages\web3\contract\contract.py", line 461, in call
    return call_contract_function(
  File "C:\Users\Administrator\AppData\Local\Programs\Python\Python310\lib\site-packages\web3\contract\utils.py", line 129, in call_contract_function
    raise BadFunctionCallOutput(msg) from e
web3.exceptions.BadFunctionCallOutput: Could not transact with/call contract function, is contract deployed correctly and chain synced?

During handling of the above exception, another exception occurred:

Traceback (most recent call last):
  File "D:\Python\alpha-kcc-dex-bot\AlphaBot.py", line 5347, in runLoop
    run()
  File "D:\Python\alpha-kcc-dex-bot\AlphaBot.py", line 4795, in run
    tokens = reload_tokens_file(command_line_args.tokens, True)
  File "D:\Python\alpha-kcc-dex-bot\AlphaBot.py", line 931, in reload_tokens_file
    '_LIQUIDITY_READY': _TOKENS_saved[token['SYMBOL']]['_LIQUIDITY_READY'],
KeyError: 'ZONE'
ERROR: 2023-06-01 12:11:08,051 'ZONE'
Traceback (most recent call last):
  File "C:\Users\Administrator\AppData\Local\Programs\Python\Python310\lib\site-packages\web3\contract\utils.py", line 111, in call_contract_function
    output_data = w3.codec.decode(output_types, return_data)
  File "C:\Users\Administrator\AppData\Local\Programs\Python\Python310\lib\site-packages\eth_abi\codec.py", line 145, in decode
    return decoder(stream)
  File "C:\Users\Administrator\AppData\Local\Programs\Python\Python310\lib\site-packages\eth_abi\decoding.py", line 129, in __call__
    return self.decode(stream)
  File "C:\Users\Administrator\AppData\Local\Programs\Python\Python310\lib\site-packages\eth_utils\functional.py", line 45, in inner
    return callback(fn(*args, **kwargs))
  File "C:\Users\Administrator\AppData\Local\Programs\Python\Python310\lib\site-packages\eth_abi\decoding.py", line 175, in decode
    yield decoder(stream)
  File "C:\Users\Administrator\AppData\Local\Programs\Python\Python310\lib\site-packages\eth_abi\decoding.py", line 129, in __call__
    return self.decode(stream)
  File "C:\Users\Administrator\AppData\Local\Programs\Python\Python310\lib\site-packages\eth_abi\decoding.py", line 199, in decode
    raw_data = self.read_data_from_stream(stream)
  File "C:\Users\Administrator\AppData\Local\Programs\Python\Python310\lib\site-packages\eth_abi\decoding.py", line 306, in read_data_from_stream
    raise InsufficientDataBytes(
eth_abi.exceptions.InsufficientDataBytes: Tried to read 32 bytes.  Only got 0 bytes

The above exception was the direct cause of the following exception:

Traceback (most recent call last):
  File "D:\Python\alpha-kcc-dex-bot\AlphaBot.py", line 5347, in runLoop
    run()
  File "D:\Python\alpha-kcc-dex-bot\AlphaBot.py", line 4793, in run
    tokens = load_tokens_file(command_line_args.tokens, True)
  File "D:\Python\alpha-kcc-dex-bot\AlphaBot.py", line 664, in load_tokens_file
    '_BASE_PRICE': calculate_base_price(),
  File "C:\Users\Administrator\AppData\Local\Programs\Python\Python310\lib\site-packages\cachetools\__init__.py", line 737, in wrapper
    v = func(*args, **kwargs)
  File "D:\Python\alpha-kcc-dex-bot\AlphaBot.py", line 3067, in calculate_base_price
    reserves = pair_contract.functions.getReserves().call()
  File "C:\Users\Administrator\AppData\Local\Programs\Python\Python310\lib\site-packages\web3\contract\contract.py", line 461, in call
    return call_contract_function(
  File "C:\Users\Administrator\AppData\Local\Programs\Python\Python310\lib\site-packages\web3\contract\utils.py", line 129, in call_contract_function
    raise BadFunctionCallOutput(msg) from e
web3.exceptions.BadFunctionCallOutput: Could not transact with/call contract function, is contract deployed correctly and chain synced?

During handling of the above exception, another exception occurred:

Traceback (most recent call last):
  File "D:\Python\alpha-kcc-dex-bot\AlphaBot.py", line 5347, in runLoop
    run()
  File "D:\Python\alpha-kcc-dex-bot\AlphaBot.py", line 4795, in run
    tokens = reload_tokens_file(command_line_args.tokens, True)
  File "D:\Python\alpha-kcc-dex-bot\AlphaBot.py", line 931, in reload_tokens_file
    '_LIQUIDITY_READY': _TOKENS_saved[token['SYMBOL']]['_LIQUIDITY_READY'],
KeyError: 'ZONE'
INFO: 2023-06-01 17:58:06,826 **********************************************************************************************************************
INFO: 2023-06-01 17:58:06,826 YOUR BOT IS CURRENTLY RUNNING VERSION  1.0.0
ERROR: 2023-06-01 17:58:17,817 Could not transact with/call contract function, is contract deployed correctly and chain synced?
Traceback (most recent call last):
  File "C:\Users\Administrator\AppData\Local\Programs\Python\Python310\lib\site-packages\web3\contract\utils.py", line 111, in call_contract_function
    output_data = w3.codec.decode(output_types, return_data)
  File "C:\Users\Administrator\AppData\Local\Programs\Python\Python310\lib\site-packages\eth_abi\codec.py", line 145, in decode
    return decoder(stream)
  File "C:\Users\Administrator\AppData\Local\Programs\Python\Python310\lib\site-packages\eth_abi\decoding.py", line 129, in __call__
    return self.decode(stream)
  File "C:\Users\Administrator\AppData\Local\Programs\Python\Python310\lib\site-packages\eth_utils\functional.py", line 45, in inner
    return callback(fn(*args, **kwargs))
  File "C:\Users\Administrator\AppData\Local\Programs\Python\Python310\lib\site-packages\eth_abi\decoding.py", line 175, in decode
    yield decoder(stream)
  File "C:\Users\Administrator\AppData\Local\Programs\Python\Python310\lib\site-packages\eth_abi\decoding.py", line 129, in __call__
    return self.decode(stream)
  File "C:\Users\Administrator\AppData\Local\Programs\Python\Python310\lib\site-packages\eth_abi\decoding.py", line 199, in decode
    raw_data = self.read_data_from_stream(stream)
  File "C:\Users\Administrator\AppData\Local\Programs\Python\Python310\lib\site-packages\eth_abi\decoding.py", line 306, in read_data_from_stream
    raise InsufficientDataBytes(
eth_abi.exceptions.InsufficientDataBytes: Tried to read 32 bytes.  Only got 0 bytes

The above exception was the direct cause of the following exception:

Traceback (most recent call last):
  File "D:\Python\alpha-kcc-dex-bot\AlphaBot.py", line 4793, in run
    tokens = load_tokens_file(command_line_args.tokens, True)
  File "D:\Python\alpha-kcc-dex-bot\AlphaBot.py", line 664, in load_tokens_file
    '_BASE_PRICE': calculate_base_price(),
  File "C:\Users\Administrator\AppData\Local\Programs\Python\Python310\lib\site-packages\cachetools\__init__.py", line 737, in wrapper
    v = func(*args, **kwargs)
  File "D:\Python\alpha-kcc-dex-bot\AlphaBot.py", line 3067, in calculate_base_price
    reserves = pair_contract.functions.getReserves().call()
  File "C:\Users\Administrator\AppData\Local\Programs\Python\Python310\lib\site-packages\web3\contract\contract.py", line 461, in call
    return call_contract_function(
  File "C:\Users\Administrator\AppData\Local\Programs\Python\Python310\lib\site-packages\web3\contract\utils.py", line 129, in call_contract_function
    raise BadFunctionCallOutput(msg) from e
web3.exceptions.BadFunctionCallOutput: Could not transact with/call contract function, is contract deployed correctly and chain synced?
INFO: 2023-06-01 17:58:17,883 ERROR. Please go to /log folder and open your logs: you will find more details.
ERROR: 2023-06-01 17:58:17,883 Could not transact with/call contract function, is contract deployed correctly and chain synced?
Traceback (most recent call last):
  File "C:\Users\Administrator\AppData\Local\Programs\Python\Python310\lib\site-packages\web3\contract\utils.py", line 111, in call_contract_function
    output_data = w3.codec.decode(output_types, return_data)
  File "C:\Users\Administrator\AppData\Local\Programs\Python\Python310\lib\site-packages\eth_abi\codec.py", line 145, in decode
    return decoder(stream)
  File "C:\Users\Administrator\AppData\Local\Programs\Python\Python310\lib\site-packages\eth_abi\decoding.py", line 129, in __call__
    return self.decode(stream)
  File "C:\Users\Administrator\AppData\Local\Programs\Python\Python310\lib\site-packages\eth_utils\functional.py", line 45, in inner
    return callback(fn(*args, **kwargs))
  File "C:\Users\Administrator\AppData\Local\Programs\Python\Python310\lib\site-packages\eth_abi\decoding.py", line 175, in decode
    yield decoder(stream)
  File "C:\Users\Administrator\AppData\Local\Programs\Python\Python310\lib\site-packages\eth_abi\decoding.py", line 129, in __call__
    return self.decode(stream)
  File "C:\Users\Administrator\AppData\Local\Programs\Python\Python310\lib\site-packages\eth_abi\decoding.py", line 199, in decode
    raw_data = self.read_data_from_stream(stream)
  File "C:\Users\Administrator\AppData\Local\Programs\Python\Python310\lib\site-packages\eth_abi\decoding.py", line 306, in read_data_from_stream
    raise InsufficientDataBytes(
eth_abi.exceptions.InsufficientDataBytes: Tried to read 32 bytes.  Only got 0 bytes

The above exception was the direct cause of the following exception:

Traceback (most recent call last):
  File "D:\Python\alpha-kcc-dex-bot\AlphaBot.py", line 5347, in runLoop
    run()
  File "D:\Python\alpha-kcc-dex-bot\AlphaBot.py", line 4793, in run
    tokens = load_tokens_file(command_line_args.tokens, True)
  File "D:\Python\alpha-kcc-dex-bot\AlphaBot.py", line 664, in load_tokens_file
    '_BASE_PRICE': calculate_base_price(),
  File "C:\Users\Administrator\AppData\Local\Programs\Python\Python310\lib\site-packages\cachetools\__init__.py", line 737, in wrapper
    v = func(*args, **kwargs)
  File "D:\Python\alpha-kcc-dex-bot\AlphaBot.py", line 3067, in calculate_base_price
    reserves = pair_contract.functions.getReserves().call()
  File "C:\Users\Administrator\AppData\Local\Programs\Python\Python310\lib\site-packages\web3\contract\contract.py", line 461, in call
    return call_contract_function(
  File "C:\Users\Administrator\AppData\Local\Programs\Python\Python310\lib\site-packages\web3\contract\utils.py", line 129, in call_contract_function
    raise BadFunctionCallOutput(msg) from e
web3.exceptions.BadFunctionCallOutput: Could not transact with/call contract function, is contract deployed correctly and chain synced?
ERROR: 2023-06-01 17:58:17,884 Could not transact with/call contract function, is contract deployed correctly and chain synced?
Traceback (most recent call last):
  File "C:\Users\Administrator\AppData\Local\Programs\Python\Python310\lib\site-packages\web3\contract\utils.py", line 111, in call_contract_function
    output_data = w3.codec.decode(output_types, return_data)
  File "C:\Users\Administrator\AppData\Local\Programs\Python\Python310\lib\site-packages\eth_abi\codec.py", line 145, in decode
    return decoder(stream)
  File "C:\Users\Administrator\AppData\Local\Programs\Python\Python310\lib\site-packages\eth_abi\decoding.py", line 129, in __call__
    return self.decode(stream)
  File "C:\Users\Administrator\AppData\Local\Programs\Python\Python310\lib\site-packages\eth_utils\functional.py", line 45, in inner
    return callback(fn(*args, **kwargs))
  File "C:\Users\Administrator\AppData\Local\Programs\Python\Python310\lib\site-packages\eth_abi\decoding.py", line 175, in decode
    yield decoder(stream)
  File "C:\Users\Administrator\AppData\Local\Programs\Python\Python310\lib\site-packages\eth_abi\decoding.py", line 129, in __call__
    return self.decode(stream)
  File "C:\Users\Administrator\AppData\Local\Programs\Python\Python310\lib\site-packages\eth_abi\decoding.py", line 199, in decode
    raw_data = self.read_data_from_stream(stream)
  File "C:\Users\Administrator\AppData\Local\Programs\Python\Python310\lib\site-packages\eth_abi\decoding.py", line 306, in read_data_from_stream
    raise InsufficientDataBytes(
eth_abi.exceptions.InsufficientDataBytes: Tried to read 32 bytes.  Only got 0 bytes

The above exception was the direct cause of the following exception:

Traceback (most recent call last):
  File "D:\Python\alpha-kcc-dex-bot\AlphaBot.py", line 5347, in runLoop
    run()
  File "D:\Python\alpha-kcc-dex-bot\AlphaBot.py", line 4793, in run
    tokens = load_tokens_file(command_line_args.tokens, True)
  File "D:\Python\alpha-kcc-dex-bot\AlphaBot.py", line 664, in load_tokens_file
    '_BASE_PRICE': calculate_base_price(),
  File "C:\Users\Administrator\AppData\Local\Programs\Python\Python310\lib\site-packages\cachetools\__init__.py", line 737, in wrapper
    v = func(*args, **kwargs)
  File "D:\Python\alpha-kcc-dex-bot\AlphaBot.py", line 3067, in calculate_base_price
    reserves = pair_contract.functions.getReserves().call()
  File "C:\Users\Administrator\AppData\Local\Programs\Python\Python310\lib\site-packages\web3\contract\contract.py", line 461, in call
    return call_contract_function(
  File "C:\Users\Administrator\AppData\Local\Programs\Python\Python310\lib\site-packages\web3\contract\utils.py", line 129, in call_contract_function
    raise BadFunctionCallOutput(msg) from e
web3.exceptions.BadFunctionCallOutput: Could not transact with/call contract function, is contract deployed correctly and chain synced?
INFO: 2023-06-01 18:03:05,870 **********************************************************************************************************************
INFO: 2023-06-01 18:03:05,871 YOUR BOT IS CURRENTLY RUNNING VERSION  1.0.0
INFO: 2023-06-01 18:05:36,739 **********************************************************************************************************************
INFO: 2023-06-01 18:05:36,739 YOUR BOT IS CURRENTLY RUNNING VERSION  1.0.1
INFO: 2023-06-01 18:05:58,169 46 - 90 ALPHA tokens needed to use this bot, ALPHA tokens can be purchased on alphaswap.exchange
